<?xml version="1.0"?>
<robot name="rover" xmlns:xacro="http://www.ros.org/wiki/xacro">

  <material name="grey"><color rgba="0.5 0.5 0.5 1.0"/></material>
  <material name="black"><color rgba="0.0 0.0 0.0 1.0"/></material>
  <material name="blue"><color rgba="0.0 0.0 1.0 1.0"/></material>
  <material name="lidar_mat"><color rgba="0.1 0.1 0.1 1.0"/></material>
  <material name="cam_mat"><color rgba="0.5 0.5 0.5 1.0"/></material>

  <link name="base_footprint"/>
  <joint name="base_joint" type="fixed">
    <parent link="base_footprint"/>
    <child link="base_link"/>
  </joint>

  <link name="base_link">
    <inertial>
      <mass value="5.0"/>
      <inertia ixx="0.1" ixy="0" ixz="0" iyy="0.1" iyz="0" izz="0.1"/>
    </inertial>
    <visual>
      <geometry><box size="0.4 0.3 0.1"/></geometry>
      <material name="blue"/>
    </visual>
    <collision>
      <geometry><box size="0.4 0.3 0.1"/></geometry>
    </collision>
  </link>

  <link name="left_track_vis">
    <visual><geometry><box size="0.4 0.05 0.1"/></geometry><material name="black"/></visual>
  </link>
  <joint name="lt_joint" type="fixed"><parent link="base_link"/><child link="left_track_vis"/><origin xyz="0 0.18 -0.03"/></joint>

  <link name="right_track_vis">
    <visual><geometry><box size="0.4 0.05 0.1"/></geometry><material name="black"/></visual>
  </link>
  <joint name="rt_joint" type="fixed"><parent link="base_link"/><child link="right_track_vis"/><origin xyz="0 -0.18 -0.03"/></joint>

  <link name="left_wheel"><collision><geometry><cylinder radius="0.05" length="0.03"/></geometry></collision><inertial><mass value="0.2"/><inertia ixx="0.01" ixy="0" ixz="0" iyy="0.01" iyz="0" izz="0.01"/></inertial></link>
  <joint name="left_wheel_joint" type="continuous"><parent link="base_link"/><child link="left_wheel"/><origin xyz="0 0.17 -0.05" rpy="1.5708 0 0"/><axis xyz="0 0 -1"/></joint>

  <link name="right_wheel"><collision><geometry><cylinder radius="0.05" length="0.03"/></geometry></collision><inertial><mass value="0.2"/><inertia ixx="0.01" ixy="0" ixz="0" iyy="0.01" iyz="0" izz="0.01"/></inertial></link>
  <joint name="right_wheel_joint" type="continuous"><parent link="base_link"/><child link="right_wheel"/><origin xyz="0 -0.17 -0.05" rpy="1.5708 0 0"/><axis xyz="0 0 -1"/></joint>

  <link name="f_caster"><collision><geometry><sphere radius="0.05"/></geometry></collision><inertial><mass value="0.01"/><inertia ixx="0.001" ixy="0" ixz="0" iyy="0.001" iyz="0" izz="0.001"/></inertial></link>
  <joint name="f_caster_j" type="fixed"><parent link="base_link"/><child link="f_caster"/><origin xyz="0.18 0 -0.05"/></joint>
  <gazebo reference="f_caster"><mu1>0.0</mu1><mu2>0.0</mu2></gazebo>

  <link name="r_caster"><collision><geometry><sphere radius="0.05"/></geometry></collision><inertial><mass value="0.01"/><inertia ixx="0.001" ixy="0" ixz="0" iyy="0.001" iyz="0" izz="0.001"/></inertial></link>
  <joint name="r_caster_j" type="fixed"><parent link="base_link"/><child link="r_caster"/><origin xyz="-0.18 0 -0.05"/></joint>
  <gazebo reference="r_caster"><mu1>0.0</mu1><mu2>0.0</mu2></gazebo>

  <xacro:macro name="add_ultrasonic" params="name xyz rpy topic">
    <link name="${name}_link">
      <visual>
        <geometry><sphere radius="0.015"/></geometry>
        <material name="grey"/>
      </visual>
    </link>

    <joint name="${name}_joint" type="fixed">
      <origin xyz="${xyz}" rpy="${rpy}"/>
      <parent link="base_link"/>
      <child link="${name}_link"/>
    </joint>

    <gazebo reference="${name}_link">
      <sensor name="${name}" type="ray">
        <always_on>true</always_on>
        <update_rate>10</update_rate>
        <visualize>true</visualize>
        <ray>
          <scan>
            <horizontal>
              <samples>10</samples>
              <resolution>1</resolution>
              <min_angle>-0.3927</min_angle>
              <max_angle>0.3927</max_angle>
            </horizontal>
          </scan>
          <range>
            <min>0.02</min>
            <max>2.0</max>
            <resolution>0.01</resolution>
          </range>
        </ray>
        <plugin name="${name}_plugin" filename="libgazebo_ros_ray_sensor.so">
          <ros>
            <remapping>~/out:=${topic}</remapping>
          </ros>
          <output_type>sensor_msgs/LaserScan</output_type>
          <frame_name>${name}_link</frame_name>
        </plugin>
      </sensor>
    </gazebo>
  </xacro:macro>

  <xacro:add_ultrasonic name="us0_front"       xyz="0.23 0 0.12"     rpy="0 0 0"        topic="/us_sensor/front"/>
  <xacro:add_ultrasonic name="us1_front_left"  xyz="0.19 0.19 0.12"  rpy="0 0 0.7854"   topic="/us_sensor/front_left"/>
  <xacro:add_ultrasonic name="us2_left"        xyz="0 0.23 0.12"     rpy="0 0 1.5708"   topic="/us_sensor/left"/>
  <xacro:add_ultrasonic name="us3_rear_left"   xyz="-0.19 0.19 0.12" rpy="0 0 2.3562"   topic="/us_sensor/rear_left"/>
  <xacro:add_ultrasonic name="us4_rear"        xyz="-0.23 0 0.12"    rpy="0 0 3.14159"  topic="/us_sensor/rear"/>
  <xacro:add_ultrasonic name="us5_rear_right"  xyz="-0.19 -0.19 0.12" rpy="0 0 -2.3562" topic="/us_sensor/rear_right"/>
  <xacro:add_ultrasonic name="us6_right"       xyz="0 -0.23 0.12"    rpy="0 0 -1.5708"  topic="/us_sensor/right"/>
  <xacro:add_ultrasonic name="us7_front_right" xyz="0.19 -0.19 0.12" rpy="0 0 -0.7854"  topic="/us_sensor/front_right"/>

  <link name="lidar_link">
    <visual><geometry><cylinder radius="0.03" length="0.05"/></geometry><material name="lidar_mat"/></visual>
    <inertial><mass value="0.1"/><inertia ixx="0.001" ixy="0" ixz="0" iyy="0.001" iyz="0" izz="0.001"/></inertial>
  </link>
  <joint name="lidar_joint" type="fixed"><parent link="base_link"/><child link="lidar_link"/><origin xyz="0.2 0 0.15"/></joint>

  <gazebo reference="lidar_link">
    <sensor name="lidar" type="ray">
      <always_on>true</always_on>
      <update_rate>20</update_rate>
      <visualize>true</visualize>
      <ray>
        <scan>
          <horizontal>
            <samples>360</samples>
            <resolution>1</resolution>
            <min_angle>-3.14159</min_angle>
            <max_angle>3.14159</max_angle>
          </horizontal>
        </scan>
        <range>
          <min>0.12</min>
          <max>12.0</max>
        </range>
      </ray>
      <plugin name="lidar_plugin" filename="libgazebo_ros_ray_sensor.so">
        <ros>
          <remapping>~/out:=/scan</remapping>
        </ros>
        <output_type>sensor_msgs/LaserScan</output_type>
        <frame_name>lidar_link</frame_name>
      </plugin>
    </sensor>
  </gazebo>

  <link name="camera_link">
    <visual>
      <geometry>
        <box size="0.05 0.05 0.05"/>
      </geometry>
      <material name="blue"/>
    </visual>
  </link>

  <joint name="camera_joint" type="fixed">
    <parent link="base_link"/>
    <child link="camera_link"/>
    <origin xyz="0.3 0 0.1" rpy="0 0 0"/> 
  </joint>
  
  <link name="camera_optical_link"/>
  <joint name="camera_optical_joint" type="fixed">
    <parent link="camera_link"/>
    <child link="camera_optical_link"/>
    <origin xyz="0 0 0" rpy="-1.57 0 -1.57"/> 
  </joint>

  <gazebo reference="camera_link">
    <sensor name="camera" type="depth">
      <visualize>true</visualize>
      <update_rate>30.0</update_rate>
      <camera name="head">
        <horizontal_fov>1.047198</horizontal_fov>
        <image>
          <width>640</width>
          <height>480</height>
          <format>R8G8B8</format>
        </image>
        <clip>
          <near>0.05</near>
          <far>8.0</far>
        </clip>
      </camera>
      <plugin name="camera_controller" filename="libgazebo_ros_camera.so">
        <frame_name>camera_optical_link</frame_name>
        <min_depth>0.1</min_depth>
        <max_depth>100.0</max_depth>
      </plugin>
    </sensor>
  </gazebo>

  <link name="imu_link">
    <visual>
      <geometry>
        <box size="0.02 0.02 0.02"/>
      </geometry>
      <material name="black"/>
    </visual>
  </link>

  <joint name="imu_joint" type="fixed">
    <parent link="base_link"/>
    <child link="imu_link"/>
    <origin xyz="0 0 0.1" rpy="0 0 0"/>
  </joint>

  <gazebo reference="imu_link">
  <sensor name="imu_sensor" type="imu">
    <always_on>true</always_on>
    <update_rate>100</update_rate>
    <visualize>true</visualize>
    <plugin filename="libgazebo_ros_imu_sensor.so" name="imu_plugin">
      <ros>
        <namespace>/</namespace>
        <remapping>~/out:=/imu/data</remapping>
      </ros>
      <initial_orientation_as_reference>false</initial_orientation_as_reference>
      <frame_name>imu_link</frame_name>
      <update_rate>100.0</update_rate>
    </plugin>
  </sensor>
</gazebo>

  <link name="gps_link">
    <visual>
      <geometry>
        <box size="0.02 0.02 0.02"/>
      </geometry>
      <material name="black"/>
    </visual>
  </link>

  <joint name="gps_joint" type="fixed">
    <parent link="base_link"/>
    <child link="gps_link"/>
    <origin xyz="-0.1 0 0.15" rpy="0 0 0"/>
  </joint>

  <gazebo reference="gps_link">
    <sensor name="gps_sensor" type="gps">
      <always_on>true</always_on>
      <update_rate>1.0</update_rate>
      <plugin name="gps_controller" filename="libgazebo_ros_gps_sensor.so">
        <ros>
          <remapping>~/out:=/gps/fix</remapping>
        </ros>
        <frame_name>gps_link</frame_name>
      </plugin>
    </sensor>
  </gazebo>

  <gazebo>
    <plugin name="diff_drive" filename="libgazebo_ros_diff_drive.so">
      
      <left_joint>left_wheel_joint</left_joint>
      <right_joint>right_wheel_joint</right_joint>
      <wheel_separation>0.34</wheel_separation>
      <wheel_diameter>0.10</wheel_diameter>

      <max_wheel_torque>200</max_wheel_torque>
      <max_wheel_acceleration>10.0</max_wheel_acceleration>

      <odometry_frame>odom</odometry_frame>
      <robot_base_frame>base_footprint</robot_base_frame>

      <publish_odom>true</publish_odom>
      <publish_odom_tf>true</publish_odom_tf> 
      <publish_wheel_tf>true</publish_wheel_tf>
      

    </plugin>
  </gazebo>

</robot>